2024-10-12 06:31:20 | ERROR    | __main__:run:158 | An error has been caught in function 'run', process 'MainProcess' (3722), thread 'MainThread' (140414271228800): - {}
Traceback (most recent call last):
  File "/home/runner/work/epic_free/epic_free/epic/src/claim.py", line 151, in stash
    await self.claim_epic_games(context)
  File "/home/runner/work/epic_free/epic_free/epic/src/claim.py", line 98, in claim_epic_games
    if await epic.authorize(page):
  File "/home/runner/work/epic_free/epic_free/epic/src/epic_games/agent.py", line 260, in authorize
    match await self._login(page):
  File "/home/runner/work/epic_free/epic_free/epic/src/epic_games/agent.py", line 241, in _login
    await page.click("//button[@aria-label='Continue']")
  File "/opt/hostedtoolcache/Python/3.10.15/x64/lib/python3.10/site-packages/playwright/async_api/_generated.py", line 9625, in click
    await self._impl_obj.click(
  File "/opt/hostedtoolcache/Python/3.10.15/x64/lib/python3.10/site-packages/playwright/_impl/_page.py", line 777, in click
    return await self._main_frame.click(**locals_to_params(locals()))
  File "/opt/hostedtoolcache/Python/3.10.15/x64/lib/python3.10/site-packages/playwright/_impl/_frame.py", line 488, in click
    await self._channel.send("click", locals_to_params(locals()))
  File "/opt/hostedtoolcache/Python/3.10.15/x64/lib/python3.10/site-packages/playwright/_impl/_connection.py", line 59, in send
    return await self._connection.wrap_api_call(
  File "/opt/hostedtoolcache/Python/3.10.15/x64/lib/python3.10/site-packages/playwright/_impl/_connection.py", line 514, in wrap_api_call
    raise rewrite_error(error, f"{parsed_st['apiName']}: {error}") from None
Exception: Page.click: Connection closed while reading from the driver

During handling of the above exception, another exception occurred:

Traceback (most recent call last):
  File "/home/runner/work/epic_free/epic_free/epic/src/claim.py", line 162, in <module>
    asyncio.run(run())
  File "/opt/hostedtoolcache/Python/3.10.15/x64/lib/python3.10/asyncio/runners.py", line 44, in run
    return loop.run_until_complete(main)
  File "/opt/hostedtoolcache/Python/3.10.15/x64/lib/python3.10/asyncio/base_events.py", line 636, in run_until_complete
    self.run_forever()
  File "/opt/hostedtoolcache/Python/3.10.15/x64/lib/python3.10/asyncio/base_events.py", line 603, in run_forever
    self._run_once()
  File "/opt/hostedtoolcache/Python/3.10.15/x64/lib/python3.10/asyncio/base_events.py", line 1909, in _run_once
    handle._run()
  File "/opt/hostedtoolcache/Python/3.10.15/x64/lib/python3.10/asyncio/events.py", line 80, in _run
    self._context.run(self._callback, *self._args)
> File "/home/runner/work/epic_free/epic_free/epic/src/claim.py", line 158, in run
    await agent.stash()
  File "/home/runner/work/epic_free/epic_free/epic/src/claim.py", line 139, in stash
    async with async_playwright() as p:
  File "/opt/hostedtoolcache/Python/3.10.15/x64/lib/python3.10/site-packages/playwright/async_api/_context_manager.py", line 57, in __aexit__
    await self._connection.stop_async()
  File "/opt/hostedtoolcache/Python/3.10.15/x64/lib/python3.10/site-packages/playwright/_impl/_connection.py", line 285, in stop_async
    self.cleanup()
  File "/opt/hostedtoolcache/Python/3.10.15/x64/lib/python3.10/site-packages/playwright/_impl/_connection.py", line 297, in cleanup
    callback.future.set_exception(self._closed_error)
asyncio.exceptions.InvalidStateError: invalid state
