2025-03-12 06:32:25 | INFO    | __main__:stash:131 | run - {'image': '20231121', 'version': '0.10.1.post2', 'role': 'EpicPlayer', 'headless': True}
2025-03-12 06:32:33 | INFO    | __main__:claim_epic_games:97 | Try to flush cookie - {'task': 'claim_epic_games'}
2025-03-12 06:33:03 | WARNING    | epic_games.agent:authorize:266 | 执行超时 - {'task': 'authorize', 'retry': 0}
2025-03-12 06:33:06 | INFO    | epic_games.agent:_login:237 | login-with-email - {'url': 'https://www.epicgames.com/id/login?lang=en-US&noHostRedirect=true&redirectUrl=https://store.epicgames.com/en-US/free-games&__cf_chl_rt_tk=bqkg2dZDsGDEVYr6uInQPtU4rbuseswToGb.ofUdEwQ-1741732386-1.0.1.1-3ESyu_cbE3kF8.fCtLve5yfjdn1Ljl0A4IRGw3USljQ'}
2025-03-12 06:33:36 | WARNING    | epic_games.agent:authorize:266 | 执行超时 - {'task': 'authorize', 'retry': 1}
2025-03-12 06:33:39 | INFO    | epic_games.agent:_login:237 | login-with-email - {'url': 'https://www.epicgames.com/id/login?lang=en-US&noHostRedirect=true&redirectUrl=https://store.epicgames.com/en-US/free-games&__cf_chl_rt_tk=34pu..GEEligshtMVpG.aNSGpbEDR5jQ_D7FcT2Jyh8-1741732419-1.0.1.1-L0w8PbfBbKVecK6HoNGXtr9ZSyz32olAm1SE9K7KV_c'}
2025-03-12 06:34:09 | WARNING    | epic_games.agent:authorize:266 | 执行超时 - {'task': 'authorize', 'retry': 2}
2025-03-12 06:34:10 | ERROR    | __main__:run:158 | An error has been caught in function 'run', process 'MainProcess' (3418), thread 'MainThread' (139724362615680): - {}
Traceback (most recent call last):
  File "/home/runner/work/epic_free/epic_free/epic/src/claim.py", line 162, in <module>
    asyncio.run(run())
  File "/opt/hostedtoolcache/Python/3.10.16/x64/lib/python3.10/asyncio/runners.py", line 44, in run
    return loop.run_until_complete(main)
  File "/opt/hostedtoolcache/Python/3.10.16/x64/lib/python3.10/asyncio/base_events.py", line 636, in run_until_complete
    self.run_forever()
  File "/opt/hostedtoolcache/Python/3.10.16/x64/lib/python3.10/asyncio/base_events.py", line 603, in run_forever
    self._run_once()
  File "/opt/hostedtoolcache/Python/3.10.16/x64/lib/python3.10/asyncio/base_events.py", line 1909, in _run_once
    handle._run()
  File "/opt/hostedtoolcache/Python/3.10.16/x64/lib/python3.10/asyncio/events.py", line 80, in _run
    self._context.run(self._callback, *self._args)
> File "/home/runner/work/epic_free/epic_free/epic/src/claim.py", line 158, in run
    await agent.stash()
  File "/home/runner/work/epic_free/epic_free/epic/src/claim.py", line 151, in stash
    await self.claim_epic_games(context)
  File "/home/runner/work/epic_free/epic_free/epic/src/claim.py", line 98, in claim_epic_games
    if await epic.authorize(page):
  File "/home/runner/work/epic_free/epic_free/epic/src/epic_games/agent.py", line 269, in authorize
    raise RuntimeError(f"Failed to flush token - agent={self.__class__.__name__}")
RuntimeError: Failed to flush token - agent=EpicGames
