{"text": "2025-03-28 06:36:07 | INFO    | __main__:stash:131 | run - {'image': '20231121', 'version': '0.10.1.post2', 'role': 'EpicPlayer', 'headless': True}\n", "record": {"elapsed": {"repr": "0:00:01.248215", "seconds": 1.248215}, "exception": null, "extra": {"image": "20231121", "version": "0.10.1.post2", "role": "EpicPlayer", "headless": true}, "file": {"name": "claim.py", "path": "/home/runner/work/epic_free/epic_free/epic/src/claim.py"}, "function": "stash", "level": {"icon": "ℹ️", "name": "INFO", "no": 20}, "line": 131, "message": "run", "module": "claim", "name": "__main__", "process": {"id": 3472, "name": "MainProcess"}, "thread": {"id": 140611245919104, "name": "MainThread"}, "time": {"repr": "2025-03-28 06:36:07.878792+08:00", "timestamp": 1743114967.878792}}}
{"text": "2025-03-28 06:36:40 | ERROR    | __main__:run:158 | An error has been caught in function 'run', process 'MainProcess' (3472), thread 'MainThread' (140611245919104): - {}\nTraceback (most recent call last):\n  File \"/home/runner/work/epic_free/epic_free/epic/src/claim.py\", line 162, in <module>\n    asyncio.run(run())\n  File \"/opt/hostedtoolcache/Python/3.10.16/x64/lib/python3.10/asyncio/runners.py\", line 44, in run\n    return loop.run_until_complete(main)\n  File \"/opt/hostedtoolcache/Python/3.10.16/x64/lib/python3.10/asyncio/base_events.py\", line 636, in run_until_complete\n    self.run_forever()\n  File \"/opt/hostedtoolcache/Python/3.10.16/x64/lib/python3.10/asyncio/base_events.py\", line 603, in run_forever\n    self._run_once()\n  File \"/opt/hostedtoolcache/Python/3.10.16/x64/lib/python3.10/asyncio/base_events.py\", line 1909, in _run_once\n    handle._run()\n  File \"/opt/hostedtoolcache/Python/3.10.16/x64/lib/python3.10/asyncio/events.py\", line 80, in _run\n    self._context.run(self._callback, *self._args)\n> File \"/home/runner/work/epic_free/epic_free/epic/src/claim.py\", line 158, in run\n    await agent.stash()\n  File \"/home/runner/work/epic_free/epic_free/epic/src/claim.py\", line 149, in stash\n    if not await self.prelude_with_context(context):\n  File \"/home/runner/work/epic_free/epic_free/epic/src/claim.py\", line 73, in prelude_with_context\n    await page.goto(url, wait_until=\"networkidle\")\n  File \"/opt/hostedtoolcache/Python/3.10.16/x64/lib/python3.10/site-packages/playwright/async_api/_generated.py\", line 8987, in goto\n    await self._impl_obj.goto(\n  File \"/opt/hostedtoolcache/Python/3.10.16/x64/lib/python3.10/site-packages/playwright/_impl/_page.py\", line 552, in goto\n    return await self._main_frame.goto(**locals_to_params(locals()))\n  File \"/opt/hostedtoolcache/Python/3.10.16/x64/lib/python3.10/site-packages/playwright/_impl/_frame.py\", line 145, in goto\n    await self._channel.send(\"goto\", locals_to_params(locals()))\n  File \"/opt/hostedtoolcache/Python/3.10.16/x64/lib/python3.10/site-packages/playwright/_impl/_connection.py\", line 61, in send\n    return await self._connection.wrap_api_call(\n  File \"/opt/hostedtoolcache/Python/3.10.16/x64/lib/python3.10/site-packages/playwright/_impl/_connection.py\", line 528, in wrap_api_call\n    raise rewrite_error(error, f\"{parsed_st['apiName']}: {error}\") from None\nplaywright._impl._errors.TimeoutError: Page.goto: Timeout 30000ms exceeded.\nCall log:\n  - navigating to \"https://www.epicgames.com/account/creator-programs\", waiting until \"networkidle\"\n\n", "record": {"elapsed": {"repr": "0:00:33.557480", "seconds": 33.55748}, "exception": {"type": "TimeoutError", "value": "Page.goto: Timeout 30000ms exceeded.\nCall log:\n  - navigating to \"https://www.epicgames.com/account/creator-programs\", waiting until \"networkidle\"\n", "traceback": true}, "extra": {}, "file": {"name": "claim.py", "path": "/home/runner/work/epic_free/epic_free/epic/src/claim.py"}, "function": "run", "level": {"icon": "❌", "name": "ERROR", "no": 40}, "line": 158, "message": "An error has been caught in function 'run', process 'MainProcess' (3472), thread 'MainThread' (140611245919104):", "module": "claim", "name": "__main__", "process": {"id": 3472, "name": "MainProcess"}, "thread": {"id": 140611245919104, "name": "MainThread"}, "time": {"repr": "2025-03-28 06:36:40.188057+08:00", "timestamp": 1743115000.188057}}}
